Workbook

Sheet HOW TO
A1: Content ID cấu trúc: [Chương trình]_[Format]_[Hình thức học (nếu có)]_[Hook/Nội dung chính]_[MMYY]_[PostID]
A2: DHND_Reels_HuongDiTrienVong_0226_3960
A3: Duc_Album_Online1Kem1_PhaVoRaoCao_0926_5171
A4: Trường | B4: Chú thích | C4: Ví dụ trong Content ID
A5: Chương trình | B5: Cột Key A trong sheet Mapping | C5: DHND
C6: DHHQ
C7: Duc
C8: TBN
A9: Format | B9: 1 ảnh | C9: Photo
B10: Nhiều ảnh | C10: Album
B11: Reels/Video | C11: Reels
B12: Carousel | C12: Carousel
A13: Hình thức học (áp dụng cho khóa học tiếng) | B13: Online | C13: Online
B14: Online 1 Kèm 1 | C14: Online1Kem1
B15: Offline | C15: Offline
A16: Hook/Nội dung chính | B16: Hook | C16: QuocGiaHangDau
B17: Nội dung chương trình | C17: DieuDuong2026
B18: Hook | C18: NangTrinhCapToc
A19: MMYY | B19: Tháng năm đăng bài | C19: 0526
C20: 0425
A21: PostID | B21: 4 ký tự cuối trong link post | C21: 5171
C22: 4997

Sheet BENCHMARK
A1: BENCHMARK – Target Cost per Conversation theo chương trình
A2: Sửa tại đây → Toàn bộ STATUS trong file tự cập nhật | KHÔNG sửa công thức ở sheet khác
A3: Program Code | B3: Target Cost/Conv (VNĐ) ≤ | C3: Target CTR (%) ≥ [tuỳ chọn] | D3: Ghi chú
A4: =Mapping!B4 -> Du học nghề Đức | B4: 150000 | C4: 1.5 | D4: Audience hẹp, conv chất lượng cao
A5: =Mapping!B5 -> Ngày hội DHD | B5: 180000 | C5: 1 | D5: Event – conv linh hoạt
A6: =Mapping!B6 -> Du học Đức | B6: 150000 | C6: 1.5 | D6: Tương tự Du học nghề Đức
A7: =Mapping!B7 -> Du học Hàn Quốc | B7: 180000 | C7: 1 | D7: Brandname chưa mạnh
A8: =Mapping!B8 -> CDVBA | B8: 180000 | C8: 1 | D8: Audience hẹp
A9: =Mapping!B9 -> Tiếng Đức | B9: 150000 | C9: 1.5
A10: =Mapping!B10 -> Kỳ thi OSD | B10: 150000 | C10: 1 | D10: Kỳ thi ngắn hạn
A11: =Mapping!B12 -> Tiếng Pháp | B11: 150000 | C11: 1.5
A12: =Mapping!B13 -> Tiếng Hàn | B12: 100000 | C12: 1.5 | D12: Volume rộng
A13: =Mapping!B14 -> Tiếng Trung | B13: 100000 | C13: 1.5 | D13: Volume rộng
A14: =Mapping!B15 -> Tiếng Thái | B14: 100000 | C14: 1.5 | D14: Reach tự nhiên tốt
A15: =Mapping!B16 -> Tiếng Nhật | B15: 150000 | C15: 1 | D15: Brandname yếu, chỉ có online 1 kèm 1
A16: =Mapping!B17 -> Tiếng Tây Ban Nha | B16: 160000 | C16: 1 | D16: Audience hẹp
A17: =Mapping!B18 -> Tiếng Ý | B17: 150000 | C17: 1 | D17: Audience hẹp, chỉ có online 1 kèm 1
A18: =Mapping!B19 -> Tiếng Nga | B18: 150000 | C18: 1 | D18: Audience hẹp, chỉ có online 1 kèm 1
A19: =Mapping!B20 -> EduCRM | B19: 150000 | C19: 1.3 | D19: Dựa trên lịch sử chạy Alltime
A20: =Mapping!B21 -> Thuê Phòng | B20: 135000 | C20: 2 | D20: Dựa trên lịch sử chạy Alltime
A21: =Mapping!B22
A22: =Mapping!B23
A24: DEFAULT | B24: 150000 | C24: 2 | D24: Fallback – KHÔNG xóa dòng này
A25: Dòng DEFAULT là fallback bắt buộc – KHÔNG xóa | Thêm chương trình mới phía TRÊN dòng DEFAULT

Sheet Mapping
A1: Mapping – Content ID prefix → Program Code
A2: Key = phần đầu của Content ID (trước dấu _ đầu tiên) | Thêm dòng mới khi có program mới
A3: Key (prefix trong Content ID) | B3: Program Code
A4: DHND | B4: Du học nghề Đức
A5: NgayHoiDHD | B5: Ngày hội DHD
A6: DHD | B6: Du học Đức
A7: DHHQ | B7: Du học Hàn Quốc
A8: CDVBA | B8: CDVBA
A9: Duc | B9: Tiếng Đức
A10: OSD | B10: Kỳ thi OSD
A11: HDTOSD | B11: Kỳ thi OSD
A12: Phap | B12: Tiếng Pháp
A13: Han | B13: Tiếng Hàn
A14: Trung | B14: Tiếng Trung
... A26: DEFAULT | B26: DEFAULT
A27: Thêm keyword mới phía TRÊN dòng DEFAULT | Key phải khớp prefix của Ad Name thực tế

Sheet RAW_DATA
A1: Z
A2: CÁCH PASTE: Ads Manager → Breakdown: Daily → Export CSV → Copy từ hàng dữ liệu (KHÔNG copy header) → Paste từ ô A5 | Cột K–N là helper tự tính – KHÔNG xóa, KHÔNG sửa
A3: Tên cột Meta Ads Manager: Campaign Name | Ad Set Name | Ad Name | Date | Reach | Impressions | CTR (all) | Messaging Conversations Started | Cost per Messaging Conversation | Amount Spent | K3: HELPER – Tự động tính (KHÔNG sửa)
A4: Campaign Name | B4: Ad Set Name | C4: Ad Name (Content ID) | D4: Date (YYYY-MM-DD) | E4: Reach | F4: Impressions | G4: CTR (%) | H4: Results | I4: Cost per Results | J4: Amount Spent (VNĐ) | K4: Composite Key (Ad | AdSet) | L4: Program (auto-detect) | M4: Week_Start (Thứ 2) | N4: Month (YYYY-MM)
A5: Mess - Cho thuê phòng - 27.09.2024 | B5: HCM [18-55] | C5: ThuePhong_Album_ThuePhongGiaTot_0622_0460 | D5: 46162 | E5: 160 | F5: 182 | G5: 4.3956044 | J5: 23334 | K5: =IF(C5="","",C5&" | "&B5) -> ThuePhong_Album_ThuePhongGiaTot_0622_0460 | HCM [18-55] | L5: {=IF(C5="","",IFERROR(VLOOKUP(IFERROR(LEFT(C5,FIND("_",C5)-1),C5),Mapping!$A:$B,2,FALSE),"DEFAULT"))} -> Thuê Phòng | M5: =D5-WEEKDAY(D5,2)+1 -> 46160 | N5: {=IF(D5:D4000="","", TEXT(D5:D4000,"yyyy-mm") )} -> 2026-05
A6: Mess - Cho thuê phòng - 27.09.2024 | B6: HCM [18-55] | C6: ThuePhong_Album_UuDaiPhongTraining_0622_5833 | D6: 46162 | E6: 59 | F6: 80 | G6: 5 | J6: 6324 | K6: =IF(C6="","",C6&" | "&B6) -> ThuePhong_Album_UuDaiPhongTraining_0622_5833 | HCM [18-55] | L6: {=IF(C6="","",IFERROR(VLOOKUP(IFERROR(LEFT(C6,FIND("_",C6)-1),C6),Mapping!$A:$B,2,FALSE),"DEFAULT"))} -> Thuê Phòng | M6: =D6-WEEKDAY(D6,2)+1 -> 46160 | N6: 2026-05
A7: Mess - Cho thuê phòng - 27.09.2024 | B7: Interest [18-55] | C7: ThuePhong_Album_ThuePhongGiaTot_0622_0460 | D7: 46162 | E7: 1207 | F7: 1834 | G7: 2.344602 | H7: 2 | I7: 126551.5 | J7: 253103 | K7: =IF(C7="","",C7&" | "&B7) -> ThuePhong_Album_ThuePhongGiaTot_0622_0460 | Interest [18-55] | L7: {=IF(C7="","",IFERROR(VLOOKUP(IFERROR(LEFT(C7,FIND("_",C7)-1),C7),Mapping!$A:$B,2,FALSE),"DEFAULT"))} -> Thuê Phòng | M7: =D7-WEEKDAY(D7,2)+1 -> 46160 | N7: 2026-05
A8: Mess - Cho thuê phòng - 27.09.2024 | B8: HCM [18-55] | C8: ThuePhong_Album_UuDaiPhongTraining_0622_5833 | D8: 46161 | E8: 171 | F8: 230 | G8: 1.7391304 | J8: 26099 | K8: =IF(C8="","",C8&" | "&B8) -> ThuePhong_Album_UuDaiPhongTraining_0622_5833 | HCM [18-55] | L8: {=IF(C8="","",IFERROR(VLOOKUP(IFERROR(LEFT(C8,FIND("_",C8)-1),C8),Mapping!$A:$B,2,FALSE),"DEFAULT"))} -> Thuê Phòng | M8: =D8-WEEKDAY(D8,2)+1 -> 46160 | N8: 2026-05
A9: Mess - Cho thuê phòng - 27.09.2024 | B9: Interest [18-55] | C9: ThuePhong_Album_ThuePhongGiaTot_0622_0460 | D9: 46161 | E9: 1850 | F9: 2687 | G9: 1.7491626 | H9: 4 | I9: 84841 | J9: 339364 | K9: =IF(C9="","",C9&" | "&B9) -> ThuePhong_Album_ThuePhongGiaTot_0622_0460 | Interest [18-55] | L9: {=IF(C9="","",IFERROR(VLOOKUP(IFERROR(LEFT(C9,FIND("_",C9)-1),C9),Mapping!$A:$B,2,FALSE),"DEFAULT"))} -> Thuê Phòng | M9: =D9-WEEKDAY(D9,2)+1 -> 46160 | N9: 2026-05
A10: Mess - Cho thuê phòng - 27.09.2024 | B10: HCM [18-55] | C10: ThuePhong_Album_ThuePhongGiaTot_0622_0460 | D10: 46160 | E10: 156 | F10: 174 | G10: 4.5977011 | J10: 22762 | K10: =IF(C10="","",C10&" | "&B10) -> ThuePhong_Album_ThuePhongGiaTot_0622_0460 | HCM [18-55] | L10: {=IF(C10="","",IFERROR(VLOOKUP(IFERROR(LEFT(C10,FIND("_",C10)-1),C10),Mapping!$A:$B,2,FALSE),"DEFAULT"))} -> Thuê Phòng | M10: =D10-WEEKDAY(D10,2)+1 -> 46160 | N10: 2026-05
A11: Mess - Cho thuê phòng - 27.09.2024 | B11: HCM [18-55] | C11: ThuePhong_Album_UuDaiPhongTraining_0622_5833 | D11: 46160 | E11: 103 | F11: 142 | G11: 2.1126761 | J11: 17066 | K11: =IF(C11="","",C11&" | "&B11) -> ThuePhong_Album_UuDaiPhongTraining_0622_5833 | HCM [18-55] | L11: {=IF(C11="","",IFERROR(VLOOKUP(IFERROR(LEFT(C11,FIND("_",C11)-1),C11),Mapping!$A:$B,2,FALSE),"DEFAULT"))} -> Thuê Phòng | M11: =D11-WEEKDAY(D11,2)+1 -> 46160 | N11: 2026-05
A12: Mess - Cho thuê phòng - 27.09.2024 | B12: Interest [18-55] | C12: ThuePhong_Album_ThuePhongGiaTot_0622_0460 | D12: 46160 | E12: 1567 | F12: 2414 | G12: 2.029826 | H12: 4 | I12: 68537.75 | J12: 274151 | K12: =IF(C12="","",C12&" | "&B12) -> ThuePhong_Album_ThuePhongGiaTot_0622_0460 | Interest [18-55] | L12: {=IF(C12="","",IFERROR(VLOOKUP(IFERROR(LEFT(C12,FIND("_",C12)-1),C12),Mapping!$A:$B,2,FALSE),"DEFAULT"))} -> Thuê Phòng | M12: =D12-WEEKDAY(D12,2)+1 -> 46160 | N12: 2026-05
A13: Mess - Cho thuê phòng - 27.09.2024 | B13: HCM [18-55] | C13: ThuePhong_Album_ThuePhongGiaTot_0622_0460 | D13: 46159 | E13: 1 | F13: 2 | G13: 0 | J13: 24 | K13: =IF(C13="","",C13&" | "&B13) -> ThuePhong_Album_ThuePhongGiaTot_0622_0460 | HCM [18-55] | L13: {=IF(C13="","",IFERROR(VLOOKUP(IFERROR(LEFT(C13,FIND("_",C13)-1),C13),Mapping!$A:$B,2,FALSE),"DEFAULT"))} -> Thuê Phòng | M13: =D13-WEEKDAY(D13,2)+1 -> 46153 | N13: 2026-05
A14: Mess - Cho thuê phòng - 27.09.2024 | B14: HCM [18-55] | C14: ThuePhong_Album_UuDaiPhongTraining_0622_5833 | D14: 46159 | E14: 127 | F14: 169 | G14: 1.1834319 | J14: 21722 | K14: =IF(C14="","",C14&" | "&B14) -> ThuePhong_Album_UuDaiPhongTraining_0622_5833 | HCM [18-55] | L14: {=IF(C14="","",IFERROR(VLOOKUP(IFERROR(LEFT(C14,FIND("_",C14)-1),C14),Mapping!$A:$B,2,FALSE),"DEFAULT"))} -> Thuê Phòng | M14: =D14-WEEKDAY(D14,2)+1 -> 46153 | N14: 2026-05
A15: Mess - Cho thuê phòng - 27.09.2024 | B15: Interest [18-55] | C15: ThuePhong_Album_ThuePhongGiaTot_0622_0460 | D15: 46159 | E15: 838 | F15: 1240 | G15: 2.0967742 | H15: 2 | I15: 73936 | J15: 147872 | K15: =IF(C15="","",C15&" | "&B15) -> ThuePhong_Album_ThuePhongGiaTot_0622_0460 | Interest [18-55] | L15: {=IF(C15="","",IFERROR(VLOOKUP(IFERROR(LEFT(C15,FIND("_",C15)-1),C15),Mapping!$A:$B,2,FALSE),"DEFAULT"))} -> Thuê Phòng | M15: =D15-WEEKDAY(D15,2)+1 -> 46153 | N15: 2026-05
A16: Mess - Cho thuê phòng - 27.09.2024 | B16: Interest [18-55] | C16: ThuePhong_Album_ThuePhongGiaTot_0622_0460 | D16: 46158 | E16: 794 | F16: 1244 | G16: 2.4919614 | H16: 2 | I16: 88210.5 | J16: 176421 | K16: =IF(C16="","",C16&" | "&B16) -> ThuePhong_Album_ThuePhongGiaTot_0622_0460 | Interest [18-55] | L16: {=IF(C16="","",IFERROR(VLOOKUP(IFERROR(LEFT(C16,FIND("_",C16)-1),C16),Mapping!$A:$B,2,FALSE),"DEFAULT"))} -> Thuê Phòng | M16: =D16-WEEKDAY(D16,2)+1 -> 46153 | N16: 2026-05
A17: Mess - Cho thuê phòng - 27.09.2024 | B17: HCM [18-55] | C17: ThuePhong_Album_UuDaiPhongTraining_0622_5833 | D17: 46158 | E17: 103 | F17: 149 | G17: 0.67114094 | J17: 27422 | K17: =IF(C17="","",C17&" | "&B17) -> ThuePhong_Album_UuDaiPhongTraining_0622_5833 | HCM [18-55] | L17: {=IF(C17="","",IFERROR(VLOOKUP(IFERROR(LEFT(C17,FIND("_",C17)-1),C17),Mapping!$A:$B,2,FALSE),"DEFAULT"))} -> Thuê Phòng | M17: =D17-WEEKDAY(D17,2)+1 -> 46153 | N17: 2026-05
A18: Mess - Cho thuê phòng - 27.09.2024 | B18: HCM [18-55] | C18: ThuePhong_Album_ThuePhongGiaTot_0622_0460 | D18: 46158 | E18: 10 | F18: 10 | G18: 0 | J18: 1424 | K18: =IF(C18="","",C18&" | "&B18) -> ThuePhong_Album_ThuePhongGiaTot_0622_0460 | HCM [18-55] | L18: {=IF(C18="","",IFERROR(VLOOKUP(IFERROR(LEFT(C18,FIND("_",C18)-1),C18),Mapping!$A:$B,2,FALSE),"DEFAULT"))} -> Thuê Phòng | M18: =D18-WEEKDAY(D18,2)+1 -> 46153 | N18: 2026-05
A19: Mess - Cho thuê phòng - 27.09.2024 | B19: HCM [18-55] | C19: ThuePhong_Album_UuDaiPhongTraining_0622_5833 | D19: 46157 | E19: 69 | F19: 99 | G19: 4.040404 | J19: 14743 | K19: =IF(C19="","",C19&" | "&B19) -> ThuePhong_Album_UuDaiPhongTraining_0622_5833 | HCM [18-55] | L19: {=IF(C19="","",IFERROR(VLOOKUP(IFERROR(LEFT(C19,FIND("_",C19)-1),C19),Mapping!$A:$B,2,FALSE),"DEFAULT"))} -> Thuê Phòng | M19: =D19-WEEKDAY(D19,2)+1 -> 46153 | N19: 2026-05
A20: Mess - Cho thuê phòng - 27.09.2024 | B20: Interest [18-55] | C20: ThuePhong_Album_ThuePhongGiaTot_0622_0460 | D20: 46157 | E20: 664 | F20: 1071 | G20: 1.8674136 | H20: 3 | I20: 52779.333 | J20: 158338 | K20: =IF(C20="","",C20&" | "&B20) -> ThuePhong_Album_ThuePhongGiaTot_0622_0460 | Interest [18-55] | L20: {=IF(C20="","",IFERROR(VLOOKUP(IFERROR(LEFT(C20,FIND("_",C20)-1),C20),Mapping!$A:$B,2,FALSE),"DEFAULT"))} -> Thuê Phòng | M20: =D20-WEEKDAY(D20,2)+1 -> 46153 | N20: 2026-05
A21: Mess - Cho thuê phòng - 27.09.2024 | B21: HCM [18-55] | C21: ThuePhong_Album_ThuePhongGiaTot_0622_0460 | D21: 46156 | E21: 40 | F21: 47 | G21: 0 | J21: 4604 | K21: =IF(C21="","",C21&" | "&B21) -> ThuePhong_Album_ThuePhongGiaTot_0622_0460 | HCM [18-55] | L21: {=IF(C21="","",IFERROR(VLOOKUP(IFERROR(LEFT(C21,FIND("_",C21)-1),C21),Mapping!$A:$B,2,FALSE),"DEFAULT"))} -> Thuê Phòng | M21: =D21-WEEKDAY(D21,2)+1 -> 46153 | N21: 2026-05
A22: Mess - Cho thuê phòng - 27.09.2024 | B22: HCM [18-55] | C22: ThuePhong_Album_UuDaiPhongTraining_0622_5833 | D22: 46156 | E22: 102 | F22: 145 | G22: 0.68965517 | J22: 22801 | K22: =IF(C22="","",C22&" | "&B22) -> ThuePhong_Album_UuDaiPhongTraining_0622_5833 | HCM [18-55] | L22: {=IF(C22="","",IFERROR(VLOOKUP(IFERROR(LEFT(C22,FIND("_",C22)-1),C22),Mapping!$A:$B,2,FALSE),"DEFAULT"))} -> Thuê Phòng | M22: =D22-WEEKDAY(D22,2)+1 -> 46153 | N22: 2026-05
A23: Mess - Cho thuê phòng - 27.09.2024 | B23: Interest [18-55] | C23: ThuePhong_Album_ThuePhongGiaTot_0622_0460 | D23: 46156 | E23: 931 | F23: 1515 | G23: 3.30033 | H23: 3 | I23: 78177 | J23: 234531 | K23: =IF(C23="","",C23&" | "&B23) -> ThuePhong_Album_ThuePhongGiaTot_0622_0460 | Interest [18-55] | L23: {=IF(C23="","",IFERROR(VLOOKUP(IFERROR(LEFT(C23,FIND("_",C23)-1),C23),Mapping!$A:$B,2,FALSE),"DEFAULT"))} -> Thuê Phòng | M23: =D23-WEEKDAY(D23,2)+1 -> 46153 | N23: 2026-05
A24: Mess - Cho thuê phòng - 27.09.2024 | B24: HCM [18-55] | C24: ThuePhong_Album_ThuePhongGiaTot_0622_0460 | D24: 46155 | E24: 19 | F24: 20 | G24: 0 | J24: 2030 | K24: =IF(C24="","",C24&" | "&B24) -> ThuePhong_Album_ThuePhongGiaTot_0622_0460 | HCM [18-55] | L24: {=IF(C24="","",IFERROR(VLOOKUP(IFERROR(LEFT(C24,FIND("_",C24)-1),C24),Mapping!$A:$B,2,FALSE),"DEFAULT"))} -> Thuê Phòng | M24: =D24-WEEKDAY(D24,2)+1 -> 46153 | N24: 2026-05
A25: Mess - Cho thuê phòng - 27.09.2024 | B25: HCM [18-55] | C25: ThuePhong_Album_UuDaiPhongTraining_0622_5833 | D25: 46155 | E25: 175 | F25: 270 | G25: 3.7037037 | J25: 25029 | K25: =IF(C25="","",C25&" | "&B25) -> ThuePhong_Album_UuDaiPhongTraining_0622_5833 | HCM [18-55] | L25: {=IF(C25="","",IFERROR(VLOOKUP(IFERROR(LEFT(C25,FIND("_",C25)-1),C25),Mapping!$A:$B,2,FALSE),"DEFAULT"))} -> Thuê Phòng | M25: =D25-WEEKDAY(D25,2)+1 -> 46153 | N25: 2026-05
A26: Mess - Cho thuê phòng - 27.09.2024 | B26: Interest [18-55] | C26: ThuePhong_Album_ThuePhongGiaTot_0622_0460 | D26: 46155 | E26: 1575 | F26: 2519 | G26: 2.580389 | H26: 1 | I26: 347714 | J26: 347714 | K26: =IF(C26="","",C26&" | "&B26) -> ThuePhong_Album_ThuePhongGiaTot_0622_0460 | Interest [18-55] | L26: {=IF(C26="","",IFERROR(VLOOKUP(IFERROR(LEFT(C26,FIND("_",C26)-1),C26),Mapping!$A:$B,2,FALSE),"DEFAULT"))} -> Thuê Phòng | M26: =D26-WEEKDAY(D26,2)+1 -> 46153 | N26: 2026-05
A27: Mess - Cho thuê phòng - 27.09.2024 | B27: HCM [18-55] | C27: ThuePhong_Album_UuDaiPhongTraining_0622_5833 | D27: 46154 | E27: 210 | F27: 288 | G27: 3.4722222 | H27: 1 | I27: 27780 | J27: 27780 | K27: =IF(C27="","",C27&" | "&B27) -> ThuePhong_Album_UuDaiPhongTraining_0622_5833 | HCM [18-55] | L27: {=IF(C27="","",IFERROR(VLOOKUP(IFERROR(LEFT(C27,FIND("_",C27)-1),C27),Mapping!$A:$B,2,FALSE),"DEFAULT"))} -> Thuê Phòng | M27: =D27-WEEKDAY(D27,2)+1 -> 46153 | N27: 2026-05
A28: Mess - Cho thuê phòng - 27.09.2024 | B28: Interest [18-55] | C28: ThuePhong_Album_ThuePhongGiaTot_0622_0460 | D28: 46154 | E28: 1648 | F28: 2800 | G28: 1.8571429 | H28: 1 | I28: 329652 | J28: 329652 | K28: =IF(C28="","",C28&" | "&B28) -> ThuePhong_Album_ThuePhongGiaTot_0622_0460 | Interest [18-55] | L28: {=IF(C28="","",IFERROR(VLOOKUP(IFERROR(LEFT(C28,FIND("_",C28)-1),C28),Mapping!$A:$B,2,FALSE),"DEFAULT"))} -> Thuê Phòng | M28: =D28-WEEKDAY(D28,2)+1 -> 46153 | N28: 2026-05
A29: Mess - Cho thuê phòng - 27.09.2024 | B29: HCM [18-55] | C29: ThuePhong_Album_UuDaiPhongTraining_0622_5833 | D29: 46153 | E29: 272 | F29: 417 | G29: 0.47961631 | J29: 40872 | K29: =IF(C29="","",C29&" | "&B29) -> ThuePhong_Album_UuDaiPhongTraining_0622_5833 | HCM [18-55] | L29: {=IF(C29="","",IFERROR(VLOOKUP(IFERROR(LEFT(C29,FIND("_",C29)-1),C29),Mapping!$A:$B,2,FALSE),"DEFAULT"))} -> Thuê Phòng | M29: =D29-WEEKDAY(D29,2)+1 -> 46153 | N29: 2026-05
A30: Mess - Cho thuê phòng - 27.09.2024 | B30: Interest [18-55] | C30: ThuePhong_Album_ThuePhongGiaTot_0622_0460 | D30: 46153 | E30: 772 | F30: 1203 | G30: 2.1612635 | H30: 3 | I30: 57899 | J30: 173697 | K30: =IF(C30="","",C30&" | "&B30) -> ThuePhong_Album_ThuePhongGiaTot_0622_0460 | Interest [18-55] | L30: {=IF(C30="","",IFERROR(VLOOKUP(IFERROR(LEFT(C30,FIND("_",C30)-1),C30),Mapping!$A:$B,2,FALSE),"DEFAULT"))} -> Thuê Phòng | M30: =D30-WEEKDAY(D30,2)+1 -> 46153 | N30: 2026-05
A31: Mess - Cho thuê phòng - 27.09.2024 | B31: HCM [18-55] | C31: ThuePhong_Album_UuDaiPhongTraining_0622_5833 | D31: 46152 | E31: 138 | F31: 221 | G31: 2.7149321 | J31: 28992 | K31: =IF(C31="","",C31&" | "&B31) -> ThuePhong_Album_UuDaiPhongTraining_0622_5833 | HCM [18-55] | L31: {=IF(C31="","",IFERROR(VLOOKUP(IFERROR(LEFT(C31,FIND("_",C31)-1),C31),Mapping!$A:$B,2,FALSE),"DEFAULT"))} -> Thuê Phòng | M31: =D31-WEEKDAY(D31,2)+1 -> 46146 | N31: 2026-05
A32: Mess - Cho thuê phòng - 27.09.2024 | B32: Interest [18-55] | C32: ThuePhong_Album_ThuePhongGiaTot_0622_0460 | D32: 46152 | E32: 387 | F32: 607 | G32: 3.1301483 | H32: 2 | I32: 45681.5 | J32: 91363 | K32: =IF(C32="","",C32&" | "&B32) -> ThuePhong_Album_ThuePhongGiaTot_0622_0460 | Interest [18-55] | L32: {=IF(C32="","",IFERROR(VLOOKUP(IFERROR(LEFT(C32,FIND("_",C32)-1),C32),Mapping!$A:$B,2,FALSE),"DEFAULT"))} -> Thuê Phòng | M32: =D32-WEEKDAY(D32,2)+1 -> 46146 | N32: 2026-05
A33: Mess - Cho thuê phòng - 27.09.2024 | B33: HCM [18-55] | C33: ThuePhong_Album_UuDaiPhongTraining_0622_5833 | D33: 46151 | E33: 106 | F33: 142 | G33: 2.1126761 | J33: 13589 | K33: =IF(C33="","",C33&" | "&B33) -> ThuePhong_Album_UuDaiPhongTraining_0622_5833 | HCM [18-55] | L33: {=IF(C33="","",IFERROR(VLOOKUP(IFERROR(LEFT(C33,FIND("_",C33)-1),C33),Mapping!$A:$B,2,FALSE),"DEFAULT"))} -> Thuê Phòng | M33: =D33-WEEKDAY(D33,2)+1 -> 46146 | N33: 2026-05
A34: Mess - Cho thuê phòng - 27.09.2024 | B34: Interest [18-55] | C34: ThuePhong_Album_ThuePhongGiaTot_0622_0460 | D34: 46151 | E34: 199 | F34: 261 | G34: 3.0651341 | H34: 1 | I34: 36324 | J34: 36324 | K34: =IF(C34="","",C34&" | "&B34) -> ThuePhong_Album_ThuePhongGiaTot_0622_0460 | Interest [18-55] | L34: {=IF(C34="","",IFERROR(VLOOKUP(IFERROR(LEFT(C34,FIND("_",C34)-1),C34),Mapping!$A:$B,2,FALSE),"DEFAULT"))} -> Thuê Phòng | M34: =D34-WEEKDAY(D34,2)+1 -> 46146 | N34: 2026-05
A35: Mess - Cho thuê phòng - 27.09.2024 | B35: HCM [18-55] | C35: ThuePhong_Album_UuDaiPhongTraining_0622_5833 | D35: 46150 | E35: 81 | F35: 112 | G35: 3.5714286 | J35: 16262 | K35: =IF(C35="","",C35&" | "&B35) -> ThuePhong_Album_UuDaiPhongTraining_0622_5833 | HCM [18-55] | L35: {=IF(C35="","",IFERROR(VLOOKUP(IFERROR(LEFT(C35,FIND("_",C35)-1),C35),Mapping!$A:$B,2,FALSE),"DEFAULT"))} -> Thuê Phòng | M35: =D35-WEEKDAY(D35,2)+1 -> 46146 | N35: 2026-05
A36: Mess - Cho thuê phòng - 27.09.2024 | B36: Interest [18-55] | C36: ThuePhong_Album_ThuePhongGiaTot_0622_0460 | D36: 46150 | E36: 575 | F36: 917 | G36: 2.5081788 | H36: 1 | I36: 144225 | J36: 144225 | K36: =IF(C36="","",C36&" | "&B36) -> ThuePhong_Album_ThuePhongGiaTot_0622_0460 | Interest [18-55] | L36: {=IF(C36="","",IFERROR(VLOOKUP(IFERROR(LEFT(C36,FIND("_",C36)-1),C36),Mapping!$A:$B,2,FALSE),"DEFAULT"))} -> Thuê Phòng | M36: =D36-WEEKDAY(D36,2)+1 -> 46146 | N36: 2026-05
A37: Mess - Cho thuê phòng - 27.09.2024 | B37: HCM [18-55] | C37: ThuePhong_Album_UuDaiPhongTraining_0622_5833 | D37: 46149 | E37: 117 | F37: 166 | G37: 3.6144578 | J37: 27924 | K37: =IF(C37="","",C37&" | "&B37) -> ThuePhong_Album_UuDaiPhongTraining_0622_5833 | HCM [18-55] | L37: {=IF(C37="","",IFERROR(VLOOKUP(IFERROR(LEFT(C37,FIND("_",C37)-1),C37),Mapping!$A:$B,2,FALSE),"DEFAULT"))} -> Thuê Phòng | M37: =D37-WEEKDAY(D37,2)+1 -> 46146 | N37: 2026-05
A38: Mess - Cho thuê phòng - 27.09.2024 | B38: Interest [18-55] | C38: ThuePhong_Album_ThuePhongGiaTot_0622_0460 | D38: 46149 | E38: 706 | F38: 1098 | G38: 2.9143898 | H38: 3 | I38: 60654.333 | J38: 181963 | K38: =IF(C38="","",C38&" | "&B38) -> ThuePhong_Album_ThuePhongGiaTot_0622_0460 | Interest [18-55] | L38: {=IF(C38="","",IFERROR(VLOOKUP(IFERROR(LEFT(C38,FIND("_",C38)-1),C38),Mapping!$A:$B,2,FALSE),"DEFAULT"))} -> Thuê Phòng | M38: =D38-WEEKDAY(D38,2)+1 -> 46146 | N38: 2026-05
A39: Mess - Cho thuê phòng - 27.09.2024 | B39: HCM [18-55] | C39: ThuePhong_Album_UuDaiPhongTraining_0622_5833 | D39: 46148 | E39: 118 | F39: 148 | G39: 2.027027 | H39: 1 | I39: 41649 | J39: 41649 | K39: =IF(C39="","",C39&" | "&B39) -> ThuePhong_Album_UuDaiPhongTraining_0622_5833 | HCM [18-55] | L39: {=IF(C39="","",IFERROR(VLOOKUP(IFERROR(LEFT(C39,FIND("_",C39)-1),C39),Mapping!$A:$B,2,FALSE),"DEFAULT"))} -> Thuê Phòng | M39: =D39-WEEKDAY(D39,2)+1 -> 46146 | N39: 2026-05
A40: Mess - Cho thuê phòng - 27.09.2024 | B40: Interest [18-55] | C40: ThuePhong_Album_ThuePhongGiaTot_0622_0460 | D40: 46148 | E40: 847 | F40: 1367 | G40: 3.29188 | J40: 243264 | K40: =IF(C40="","",C40&" | "&B40) -> ThuePhong_Album_ThuePhongGiaTot_0622_0460 | Interest [18-55] | L40: {=IF(C40="","",IFERROR(VLOOKUP(IFERROR(LEFT(C40,FIND("_",C40)-1),C40),Mapping!$A:$B,2,FALSE),"DEFAULT"))} -> Thuê Phòng | M40: =D40-WEEKDAY(D40,2)+1 -> 46146 | N40: 2026-05
...

Sheet CONTENT_DASHBOARD
A1: Content ID (Ad Name) | B1: Program | C1: Conv 30d | D1: CPL 30d (blended) | E1: Conv 7d | F1: CPL 7d (blended) | G1: CTR 30d (weighted %) | H1: Target CPL | I1: STATUS | J1: ANNOTATION | K1: NOTE | L1: Angle / Hook (điền tay)
A2: =IFERROR(__xludf.DUMMYFUNCTION("SORT(UNIQUE(FILTER(RAW_DATA!C5:C4000,RAW_DATA!C5:C4000<>"""")))"),"CDVBA_Album_DangKyTDChung_0525_3185") -> CDVBA_Album_DangKyTDChung_0525_3185 | B2: {=IFERROR(INDEX(RAW_DATA!$L$5:$L$4000,MATCH(A2,RAW_DATA!$C$5:$C$4000,0)),"DEFAULT")} -> CDVBA | C2: =IFERROR(SUMPRODUCT((RAW_DATA!C$5:C$2000=A2)*(RAW_DATA!D$5:D$2000>=TODAY()-30)*(RAW_DATA!D$5:D$2000<=TODAY()-1)*RAW_DATA!H$5:H$2000),0) -> 2 | D2: =IF($A2="", "", IFERROR(SUMIFS(RAW_DATA!$J$5:$J$5000, RAW_DATA!$C$5:$C$5000, $A2, RAW_DATA!$D$5:$D$5000, ">="&TODAY()-30, RAW_DATA!$D$5:$D$5000, "<="&TODAY()) / $C2, "–")) -> 41238.5 | E2: =IFERROR(SUMIFS(RAW_DATA!$H$5:$H$4000,RAW_DATA!$C$5:$C$4000,$A2,RAW_DATA!$D$5:$D$4000,">="&TODAY()-7,RAW_DATA!$D$5:$D$4000,"<="&TODAY()),0) -> 1 | F2: =IFERROR(SUMIFS(RAW_DATA!$J$5:$J$4000,RAW_DATA!$C$5:$C$4000,A2,RAW_DATA!$D$5:$D$4000,">="&TODAY()-DECISION_RULES!$B$6,RAW_DATA!$D$5:$D$4000,"<="&TODAY())/E2,"–") -> 27596 | G2: =IFERROR(SUMPRODUCT((RAW_DATA!$C$5:$C$5000=A2)*(RAW_DATA!$D$5:$D$4000>=TODAY()-DECISION_RULES!$B$7)*(RAW_DATA!$D$5:$D$4000<=TODAY())*RAW_DATA!$F$5:$F$5000*RAW_DATA!$G$5:$G$5000/100)/SUMIFS(RAW_DATA!$F$5:$F$5000,RAW_DATA!$C$5:$C$5000,A2,RAW_DATA!$D$5:$D$4000,">="&TODAY()-DECISION_RULES!$B$7,RAW_DATA!$D$5:$D$4000,"<="&TODAY())*100,"–") -> 2.6519337 | H2: =IFERROR(VLOOKUP(B2,BENCHMARK!$A:$B,2,FALSE),VLOOKUP("DEFAULT",BENCHMARK!$A:$B,2,FALSE)) -> 180000 | I2: =IF(A2="","-", IF(SUMIFS(RAW_DATA!$J$5:$J$5000,RAW_DATA!$C$5:$C$5000,A2)<DECISION_RULES!$B$5,"CHUA DU DATA", IF(AND(SUMIFS(RAW_DATA!$J$5:$J$5000,RAW_DATA!$C$5:$C$5000,A2)>=DECISION_RULES!$B$5,C2=0,E2=0),"KILL", IF(AND(D2<H2,F2<H2),"SCALE", IF(AND(D2<H2,F2>H2),"WARNING", IF(AND(D2>H2,F2<H2),"TEST","KILL")))))) -> CHUA DU DATA | J2: =IF(A2="","–",IF(I2="KILL",IF(C2=0,"Da chi tieu nhung 0 conv - tat ngay, kiem tra target va content","Ca 30d va 7d deu kem - nen tat hoac thay content moi"),IF(I2="SCALE","30d va 7d deu tot - co the tang budget 20-30%",IF(I2="WARNING","30d tot nhung 7d dang xau - KHONG scale, theo doi them 3 ngay",IF(I2="TEST","30d chua tot nhung 7d dang cai thien - giu nguyen, cho them 3-5 ngay","Chua du du lieu - can chi tieu "&DECISION_RULES!$B$5&" de danh gia chinh xac"))))) -> Chua du du lieu - can chi tieu 100000 de danh gia chinh xac
A3: =IFERROR(__xludf.DUMMYFUNCTION("""COMPUTED_VALUE"""),"CDVBA_Photo_BVVorarlberg_0824_3185") -> CDVBA_Photo_BVVorarlberg_0824_3185 | B3: {=IFERROR(INDEX(RAW_DATA!$L$5:$L$4000,MATCH(A3,RAW_DATA!$C$5:$C$4000,0)),"DEFAULT")} -> CDVBA | C3: =IFERROR(SUMPRODUCT((RAW_DATA!C$5:C$2000=A3)*(RAW_DATA!D$5:D$2000>=TODAY()-30)*(RAW_DATA!D$5:D$2000<=TODAY()-1)*RAW_DATA!H$5:H$2000),0) -> 54 | D3: =IF($A3="", "", IFERROR(SUMIFS(RAW_DATA!$J$5:$J$5000, RAW_DATA!$C$5:$C$5000, $A3, RAW_DATA!$D$5:$D$5000, ">="&TODAY()-30, RAW_DATA!$D$5:$D$5000, "<="&TODAY()) / $C3, "–")) -> 92331.63 | E3: =IFERROR(SUMIFS(RAW_DATA!$H$5:$H$4000,RAW_DATA!$C$5:$C$4000,$A3,RAW_DATA!$D$5:$D$4000,">="&TODAY()-7,RAW_DATA!$D$5:$D$4000,"<="&TODAY()),0) -> 24 | F3: =IFERROR(SUMIFS(RAW_DATA!$J$5:$J$4000,RAW_DATA!$C$5:$C$4000,A3,RAW_DATA!$D$5:$D$4000,">="&TODAY()-DECISION_RULES!$B$6,RAW_DATA!$D$5:$D$4000,"<="&TODAY())/E3,"–") -> 69899.208 | G3: =IFERROR(SUMPRODUCT((RAW_DATA!$C$5:$C$5000=A3)*(RAW_DATA!$D$5:$D$4000>=TODAY()-DECISION_RULES!$B$7)*(RAW_DATA!$D$5:$D$4000<=TODAY())*RAW_DATA!$F$5:$F$5000*RAW_DATA!$G$5:$G$5000/100)/SUMIFS(RAW_DATA!$F$5:$F$5000,RAW_DATA!$C$5:$C$5000,A3,RAW_DATA!$D$5:$D$4000,">="&TODAY()-DECISION_RULES!$B$7,RAW_DATA!$D$5:$D$4000,"<="&TODAY())*100,"–") -> 2.1832064 | H3: =IFERROR(VLOOKUP(B3,BENCHMARK!$A:$B,2,FALSE),VLOOKUP("DEFAULT",BENCHMARK!$A:$B,2,FALSE)) -> 180000 | I3: =IF(A3="","-", IF(SUMIFS(RAW_DATA!$J$5:$J$5000,RAW_DATA!$C$5:$C$5000,A3)<DECISION_RULES!$B$5,"CHUA DU DATA", IF(AND(SUMIFS(RAW_DATA!$J$5:$J$5000,RAW_DATA!$C$5:$C$5000,A3)>=DECISION_RULES!$B$5,C3=0,E3=0),"KILL", IF(AND(D3<H3,F3<H3),"SCALE", IF(AND(D3<H3,F3>H3),"WARNING", IF(AND(D3>H3,F3<H3),"TEST","KILL")))))) -> SCALE | J3: =IF(A3="","–",IF(I3="KILL",IF(C3=0,"Da chi tieu nhung 0 conv - tat ngay, kiem tra target va content","Ca 30d va 7d deu kem - nen tat hoac thay content moi"),IF(I3="SCALE","30d va 7d deu tot - co the tang budget 20-30%",IF(I3="WARNING","30d tot nhung 7d dang xau - KHONG scale, theo doi them 3 ngay",IF(I3="TEST","30d chua tot nhung 7d dang cai thien - giu nguyen, cho them 3-5 ngay","Chua du du lieu - can chi tieu "&DECISION_RULES!$B$5&" de danh gia chinh xac"))))) -> 30d va 7d deu tot - co the tang budget 20-30%
A4: =IFERROR(__xludf.DUMMYFUNCTION("""COMPUTED_VALUE"""),"CDVBA_Photo_TrungCap_0924_3185") -> CDVBA_Photo_TrungCap_0924_3185 | B4: {=IFERROR(INDEX(RAW_DATA!$L$5:$L$4000,MATCH(A4,RAW_DATA!$C$5:$C$4000,0)),"DEFAULT")} -> CDVBA | C4: =IFERROR(SUMPRODUCT((RAW_DATA!C$5:C$2000=A4)*(RAW_DATA!D$5:D$2000>=TODAY()-30)*(RAW_DATA!D$5:D$2000<=TODAY()-1)*RAW_DATA!H$5:H$2000),0) -> 64 | D4: =IF($A4="", "", IFERROR(SUMIFS(RAW_DATA!$J$5:$J$5000, RAW_DATA!$C$5:$C$5000, $A4, RAW_DATA!$D$5:$D$5000, ">="&TODAY()-30, RAW_DATA!$D$5:$D$5000, "<="&TODAY()) / $C4, "–")) -> 113682.91 | E4: =IFERROR(SUMIFS(RAW_DATA!$H$5:$H$4000,RAW_DATA!$C$5:$C$4000,$A4,RAW_DATA!$D$5:$D$4000,">="&TODAY()-7,RAW_DATA!$D$5:$D$4000,"<="&TODAY()),0) -> 18 | F4: =IFERROR(SUMIFS(RAW_DATA!$J$5:$J$4000,RAW_DATA!$C$5:$C$4000,A4,RAW_DATA!$D$5:$D$4000,">="&TODAY()-DECISION_RULES!$B$6,RAW_DATA!$D$5:$D$4000,"<="&TODAY())/E4,"–") -> 106596 | G4: =IFERROR(SUMPRODUCT((RAW_DATA!$C$5:$C$5000=A4)*(RAW_DATA!$D$5:$D$4000>=TODAY()-DECISION_RULES!$B$7)*(RAW_DATA!$D$5:$D$4000<=TODAY())*RAW_DATA!$F$5:$F$5000*RAW_DATA!$G$5:$G$5000/100)/SUMIFS(RAW_DATA!$F$5:$F$5000,RAW_DATA!$C$5:$C$5000,A4,RAW_DATA!$D$5:$D$4000,">="&TODAY()-DECISION_RULES!$B$7,RAW_DATA!$D$5:$D$4000,"<="&TODAY())*100,"–") -> 1.7792349 | H4: =IFERROR(VLOOKUP(B4,BENCHMARK!$A:$B,2,FALSE),VLOOKUP("DEFAULT",BENCHMARK!$A:$B,2,FALSE)) -> 180000 | I4: =IF(A4="","-", IF(SUMIFS(RAW_DATA!$J$5:$J$5000,RAW_DATA!$C$5:$C$5000,A4)<DECISION_RULES!$B$5,"CHUA DU DATA", IF(AND(SUMIFS(RAW_DATA!$J$5:$J$5000,RAW_DATA!$C$5:$C$5000,A4)>=DECISION_RULES!$B$5,C4=0,E4=0),"KILL", IF(AND(D4<H4,F4<H4),"SCALE", IF(AND(D4<H4,F4>H4),"WARNING", IF(AND(D4>H4,F4<H4),"TEST","KILL")))))) -> SCALE | J4: =IF(A4="","–",IF(I4="KILL",IF(C4=0,"Da chi tieu nhung 0 conv - tat ngay, kiem tra target va content","Ca 30d va 7d deu kem - nen tat hoac thay content moi"),IF(I4="SCALE","30d va 7d deu tot - co the tang budget 20-30%",IF(I4="WARNING","30d tot nhung 7d dang xau - KHONG scale, theo doi them 3 ngay",IF(I4="TEST","30d chua tot nhung 7d dang cai thien - giu nguyen, cho them 3-5 ngay","Chua du du lieu - can chi tieu "&DECISION_RULES!$B$5&" de danh gia chinh xac"))))) -> 30d va 7d deu tot - co the tang budget 20-30%
A5: =IFERROR(__xludf.DUMMYFUNCTION("""COMPUTED_VALUE"""),"CDVBA_Reels_CoHoiDieuDuong_0525_3185") -> CDVBA_Reels_CoHoiDieuDuong_0525_3185 | B5: {=IFERROR(INDEX(RAW_DATA!$L$5:$L$4000,MATCH(A5,RAW_DATA!$C$5:$C$4000,0)),"DEFAULT")} -> CDVBA | C5: =IFERROR(SUMPRODUCT((RAW_DATA!C$5:C$2000=A5)*(RAW_DATA!D$5:D$2000>=TODAY()-30)*(RAW_DATA!D$5:D$2000<=TODAY()-1)*RAW_DATA!H$5:H$2000),0) -> 0 | D5: =IF($A5="", "", IFERROR(SUMIFS(RAW_DATA!$J$5:$J$5000, RAW_DATA!$C$5:$C$5000, $A5, RAW_DATA!$D$5:$D$5000, ">="&TODAY()-30, RAW_DATA!$D$5:$D$5000, "<="&TODAY()) / $C5, "–")) -> – | E5: =IFERROR(SUMIFS(RAW_DATA!$H$5:$H$4000,RAW_DATA!$C$5:$C$4000,$A5,RAW_DATA!$D$5:$D$4000,">="&TODAY()-7,RAW_DATA!$D$5:$D$4000,"<="&TODAY()),0) -> 0 | F5: =IFERROR(SUMIFS(RAW_DATA!$J$5:$J$4000,RAW_DATA!$C$5:$C$4000,A5,RAW_DATA!$D$5:$D$4000,">="&TODAY()-DECISION_RULES!$B$6,RAW_DATA!$D$5:$D$4000,"<="&TODAY())/E5,"–") -> – | G5: =IFERROR(SUMPRODUCT((RAW_DATA!$C$5:$C$5000=A5)*(RAW_DATA!$D$5:$D$4000>=TODAY()-DECISION_RULES!$B$7)*(RAW_DATA!$D$5:$D$4000<=TODAY())*RAW_DATA!$F$5:$F$5000*RAW_DATA!$G$5:$G$5000/100)/SUMIFS(RAW_DATA!$F$5:$F$5000,RAW_DATA!$C$5:$C$5000,A5,RAW_DATA!$D$5:$D$4000,">="&TODAY()-DECISION_RULES!$B$7,RAW_DATA!$D$5:$D$4000,"<="&TODAY())*100,"–") -> 1.8656716 | H5: =IFERROR(VLOOKUP(B5,BENCHMARK!$A:$B,2,FALSE),VLOOKUP("DEFAULT",BENCHMARK!$A:$B,2,FALSE)) -> 180000 | I5: =IF(A5="","-", IF(SUMIFS(RAW_DATA!$J$5:$J$5000,RAW_DATA!$C$5:$C$5000,A5)<DECISION_RULES!$B$5,"CHUA DU DATA", IF(AND(SUMIFS(RAW_DATA!$J$5:$J$5000,RAW_DATA!$C$5:$C$5000,A5)>=DECISION_RULES!$B$5,C5=0,E5=0),"KILL", IF(AND(D5<H5,F5<H5),"SCALE", IF(AND(D5<H5,F5>H5),"WARNING", IF(AND(D5>H5,F5<H5),"TEST","KILL")))))) -> CHUA DU DATA | J5: =IF(A5="","–",IF(I5="KILL",IF(C5=0,"Da chi tieu nhung 0 conv - tat ngay, kiem tra target va content","Ca 30d va 7d deu kem - nen tat hoac thay content moi"),IF(I5="SCALE","30d va 7d deu tot - co the tang budget 20-30%",IF(I5="WARNING","30d tot nhung 7d dang xau - KHONG scale, theo doi them 3 ngay",IF(I5="TEST","30d chua tot nhung 7d dang cai thien - giu nguyen, cho them 3-5 ngay","Chua du du lieu - can chi tieu "&DECISION_RULES!$B$5&" de danh gia chinh xac"))))) -> Chua du du lieu - can chi tieu 100000 de danh gia chinh xac
A6: =IFERROR(__xludf.DUMMYFUNCTION("""COMPUTED_VALUE"""),"DHD_Photo_QuocGiaHangDau_0822_3484") -> DHD_Photo_QuocGiaHangDau_0822_3484 | B6: {=IFERROR(INDEX(RAW_DATA!$L$5:$L$4000,MATCH(A6,RAW_DATA!$C$5:$C$4000,0)),"DEFAULT")} -> Du học Đức | C6: =IFERROR(SUMPRODUCT((RAW_DATA!C$5:C$2000=A6)*(RAW_DATA!D$5:D$2000>=TODAY()-30)*(RAW_DATA!D$5:D$2000<=TODAY()-1)*RAW_DATA!H$5:H$2000),0) -> 43 | D6: =IF($A6="", "", IFERROR(SUMIFS(RAW_DATA!$J$5:$J$5000, RAW_DATA!$C$5:$C$5000, $A6, RAW_DATA!$D$5:$D$5000, ">="&TODAY()-30, RAW_DATA!$D$5:$D$5000, "<="&TODAY()) / $C6, "–")) -> 153072.21 | E6: =IFERROR(SUMIFS(RAW_DATA!$H$5:$H$4000,RAW_DATA!$C$5:$C$4000,$A6,RAW_DATA!$D$5:$D$4000,">="&TODAY()-7,RAW_DATA!$D$5:$D$4000,"<="&TODAY()),0) -> 11 | F6: =IFERROR(SUMIFS(RAW_DATA!$J$5:$J$4000,RAW_DATA!$C$5:$C$4000,A6,RAW_DATA!$D$5:$D$4000,">="&TODAY()-DECISION_RULES!$B$6,RAW_DATA!$D$5:$D$4000,"<="&TODAY())/E6,"–") -> 158123.73 | G6: =IFERROR(SUMPRODUCT((RAW_DATA!$C$5:$C$5000=A6)*(RAW_DATA!$D$5:$D$4000>=TODAY()-DECISION_RULES!$B$7)*(RAW_DATA!$D$5:$D$4000<=TODAY())*RAW_DATA!$F$5:$F$5000*RAW_DATA!$G$5:$G$5000/100)/SUMIFS(RAW_DATA!$F$5:$F$5000,RAW_DATA!$C$5:$C$5000,A6,RAW_DATA!$D$5:$D$4000,">="&TODAY()-DECISION_RULES!$B$7,RAW_DATA!$D$5:$D$4000,"<="&TODAY())*100,"–") -> 1.4624756 | H6: =IFERROR(VLOOKUP(B6,BENCHMARK!$A:$B,2,FALSE),VLOOKUP("DEFAULT",BENCHMARK!$A:$B,2,FALSE)) -> 150000 | I6: =IF(A6="","-", IF(SUMIFS(RAW_DATA!$J$5:$J$5000,RAW_DATA!$C$5:$C$5000,A6)<DECISION_RULES!$B$5,"CHUA DU DATA", IF(AND(SUMIFS(RAW_DATA!$J$5:$J$5000,RAW_DATA!$C$5:$C$5000,A6)>=DECISION_RULES!$B$5,C6=0,E6=0),"KILL", IF(AND(D6<H6,F6<H6),"SCALE", IF(AND(D6<H6,F6>H6),"WARNING", IF(AND(D6>H6,F6<H6),"TEST","KILL")))))) -> KILL | J6: =IF(A6="","–",IF(I6="KILL",IF(C6=0,"Da chi tieu nhung 0 conv - tat ngay, kiem tra target va content","Ca 30d va 7d deu kem - nen tat hoac thay content moi"),IF(I6="SCALE","30d va 7d deu tot - co the tang budget 20-30%",IF(I6="WARNING","30d tot nhung 7d dang xau - KHONG scale, theo doi them 3 ngay",IF(I6="TEST","30d chua tot nhung 7d dang cai thien - giu nguyen, cho them 3-5 ngay","Chua du du lieu - can chi tieu "&DECISION_RULES!$B$5&" de danh gia chinh xac"))))) -> Ca 30d va 7d deu kem - nen tat hoac thay content moi | K6: Chỉ có 1 post QC
A7: =IFERROR(__xludf.DUMMYFUNCTION("""COMPUTED_VALUE"""),"DHHQ_Carousel_TruongTopDau_0126_3500") -> DHHQ_Carousel_TruongTopDau_0126_3500 | B7: {=IFERROR(INDEX(RAW_DATA!$L$5:$L$4000,MATCH(A7,RAW_DATA!$C$5:$C$4000,0)),"DEFAULT")} -> Du học Hàn Quốc | C7: =IFERROR(SUMPRODUCT((RAW_DATA!C$5:C$2000=A7)*(RAW_DATA!D$5:D$2000>=TODAY()-30)*(RAW_DATA!D$5:D$2000<=TODAY()-1)*RAW_DATA!H$5:H$2000),0) -> 3 | D7: =IF($A7="", "", IFERROR(SUMIFS(RAW_DATA!$J$5:$J$5000, RAW_DATA!$C$5:$C$5000, $A7, RAW_DATA!$D$5:$D$5000, ">="&TODAY()-30, RAW_DATA!$D$5:$D$5000, "<="&TODAY()) / $C7, "–")) -> 79061 | E7: =IFERROR(SUMIFS(RAW_DATA!$H$5:$H$4000,RAW_DATA!$C$5:$C$4000,$A7,RAW_DATA!$D$5:$D$4000,">="&TODAY()-7,RAW_DATA!$D$5:$D$4000,"<="&TODAY()),0) -> 0 | F7: =IFERROR(SUMIFS(RAW_DATA!$J$5:$J$4000,RAW_DATA!$C$5:$C$4000,A7,RAW_DATA!$D$5:$D$4000,">="&TODAY()-DECISION_RULES!$B$6,RAW_DATA!$D$5:$D$4000,"<="&TODAY())/E7,"–") -> – | G7: =IFERROR(SUMPRODUCT((RAW_DATA!$C$5:$C$5000=A7)*(RAW_DATA!$D$5:$D$4000>=TODAY()-DECISION_RULES!$B$7)*(RAW_DATA!$D$5:$D$4000<=TODAY())*RAW_DATA!$F$5:$F$5000*RAW_DATA!$G$5:$G$5000/100)/SUMIFS(RAW_DATA!$F$5:$F$5000,RAW_DATA!$C$5:$C$5000,A7,RAW_DATA!$D$5:$D$4000,">="&TODAY()-DECISION_RULES!$B$7,RAW_DATA!$D$5:$D$4000,"<="&TODAY())*100,"–") -> 1.5625 | H7: =IFERROR(VLOOKUP(B7,BENCHMARK!$A:$B,2,FALSE),VLOOKUP("DEFAULT",BENCHMARK!$A:$B,2,FALSE)) -> 180000 | I7: =IF(A7="","-", IF(SUMIFS(RAW_DATA!$J$5:$J$5000,RAW_DATA!$C$5:$C$5000,A7)<DECISION_RULES!$B$5,"CHUA DU DATA", IF(AND(SUMIFS(RAW_DATA!$J$5:$J$5000,RAW_DATA!$C$5:$C$5000,A7)>=DECISION_RULES!$B$5,C7=0,E7=0),"KILL", IF(AND(D7<H7,F7<H7),"SCALE", IF(AND(D7<H7,F7>H7),"WARNING", IF(AND(D7>H7,F7<H7),"TEST","KILL")))))) -> WARNING | J7: =IF(A7="","–",IF(I7="KILL",IF(C7=0,"Da chi tieu nhung 0 conv - tat ngay, kiem tra target va content","Ca 30d va 7d deu kem - nen tat hoac thay content moi"),IF(I7="SCALE","30d va 7d deu tot - co the tang budget 20-30%",IF(I7="WARNING","30d tot nhung 7d dang xau - KHONG scale, theo doi them 3 ngay",IF(I7="TEST","30d chua tot nhung 7d dang cai thien - giu nguyen, cho them 3-5 ngay","Chua du du lieu - can chi tieu "&DECISION_RULES!$B$5&" de danh gia chinh xac"))))) -> 30d tot nhung 7d dang xau - KHONG scale, theo doi them 3 ngay
A8: =IFERROR(__xludf.DUMMYFUNCTION("""COMPUTED_VALUE"""),"DHHQ_Photo_DieuDuongDHKyungin_1025_7742") -> DHHQ_Photo_DieuDuongDHKyungin_1025_7742 | B8: {=IFERROR(INDEX(RAW_DATA!$L$5:$L$4000,MATCH(A8,RAW_DATA!$C$5:$C$4000,0)),"DEFAULT")} -> Du học Hàn Quốc | C8: =IFERROR(SUMPRODUCT((RAW_DATA!C$5:C$2000=A8)*(RAW_DATA!D$5:D$2000>=TODAY()-30)*(RAW_DATA!D$5:D$2000<=TODAY()-1)*RAW_DATA!H$5:H$2000),0) -> 44 | D8: =IF($A8="", "", IFERROR(SUMIFS(RAW_DATA!$J$5:$J$5000, RAW_DATA!$C$5:$C$5000, $A8, RAW_DATA!$D$5:$D$5000, ">="&TODAY()-30, RAW_DATA!$D$5:$D$5000, "<="&TODAY()) / $C8, "–")) -> 91949.773 | E8: =IFERROR(SUMIFS(RAW_DATA!$H$5:$H$4000,RAW_DATA!$C$5:$C$4000,$A8,RAW_DATA!$D$5:$D$4000,">="&TODAY()-7,RAW_DATA!$D$5:$D$4000,"<="&TODAY()),0) -> 6 | F8: =IFERROR(SUMIFS(RAW_DATA!$J$5:$J$4000,RAW_DATA!$C$5:$C$4000,A8,RAW_DATA!$D$5:$D$4000,">="&TODAY()-DECISION_RULES!$B$6,RAW_DATA!$D$5:$D$4000,"<="&TODAY())/E8,"–") -> 145340.17 | G8: =IFERROR(SUMPRODUCT((RAW_DATA!$C$5:$C$5000=A8)*(RAW_DATA!$D$5:$D$4000>=TODAY()-DECISION_RULES!$B$7)*(RAW_DATA!$D$5:$D$4000<=TODAY())*RAW_DATA!$F$5:$F$5000*RAW_DATA!$G$5:$G$5000/100)/SUMIFS(RAW_DATA!$F$5:$F$5000,RAW_DATA!$C$5:$C$5000,A8,RAW_DATA!$D$5:$D$4000,">="&TODAY()-DECISION_RULES!$B$7,RAW_DATA!$D$5:$D$4000,"<="&TODAY())*100,"–") -> 1.4950062 | H8: =IFERROR(VLOOKUP(B8,BENCHMARK!$A:$B,2,FALSE),VLOOKUP("DEFAULT",BENCHMARK!$A:$B,2,FALSE)) -> 180000 | I8: =IF(A8="","-", IF(SUMIFS(RAW_DATA!$J$5:$J$5000,RAW_DATA!$C$5:$C$5000,A8)<DECISION_RULES!$B$5,"CHUA DU DATA", IF(AND(SUMIFS(RAW_DATA!$J$5:$J$5000,RAW_DATA!$C$5:$C$5000,A8)>=DECISION_RULES!$B$5,C8=0,E8=0),"KILL", IF(AND(D8<H8,F8<H8),"SCALE", IF(AND(D8<H8,F8>H8),"WARNING", IF(AND(D8>H8,F8<H8),"TEST","KILL")))))) -> SCALE | J8: =IF(A8="","–",IF(I8="KILL",IF(C8=0,"Da chi tieu nhung 0 conv - tat ngay, kiem tra target va content","Ca 30d va 7d deu kem - nen tat hoac thay content moi"),IF(I8="SCALE","30d va 7d deu tot - co the tang budget 20-30%",IF(I8="WARNING","30d tot nhung 7d dang xau - KHONG scale, theo doi them 3 ngay",IF(I8="TEST","30d chua tot nhung 7d dang cai thien - giu nguyen, cho them 3-5 ngay","Chua du du lieu - can chi tieu "&DECISION_RULES!$B$5&" de danh gia chinh xac"))))) -> 30d va 7d deu tot - co the tang budget 20-30%
A9: =IFERROR(__xludf.DUMMYFUNCTION("""COMPUTED_VALUE"""),"DHHQ_Photo_TruongTopDau_1124_3533") -> DHHQ_Photo_TruongTopDau_1124_3533 | B9: {=IFERROR(INDEX(RAW_DATA!$L$5:$L$4000,MATCH(A9,RAW_DATA!$C$5:$C$4000,0)),"DEFAULT")} -> Du học Hàn Quốc | C9: =IFERROR(SUMPRODUCT((RAW_DATA!C$5:C$2000=A9)*(RAW_DATA!D$5:D$2000>=TODAY()-30)*(RAW_DATA!D$5:D$2000<=TODAY()-1)*RAW_DATA!H$5:H$2000),0) -> 1 | D9: =IF($A9="", "", IFERROR(SUMIFS(RAW_DATA!$J$5:$J$5000, RAW_DATA!$C$5:$C$5000, $A9, RAW_DATA!$D$5:$D$5000, ">="&TODAY()-30, RAW_DATA!$D$5:$D$5000, "<="&TODAY()) / $C9, "–")) -> 105184 | E9: =IFERROR(SUMIFS(RAW_DATA!$H$5:$H$4000,RAW_DATA!$C$5:$C$4000,$A9,RAW_DATA!$D$5:$D$4000,">="&TODAY()-7,RAW_DATA!$D$5:$D$4000,"<="&TODAY()),0) -> 0 | F9: =IFERROR(SUMIFS(RAW_DATA!$J$5:$J$4000,RAW_DATA!$C$5:$C$4000,A9,RAW_DATA!$D$5:$D$4000,">="&TODAY()-DECISION_RULES!$B$6,RAW_DATA!$D$5:$D$4000,"<="&TODAY())/E9,"–") -> – | G9: =IFERROR(SUMPRODUCT((RAW_DATA!$C$5:$C$5000=A9)*(RAW_DATA!$D$5:$D$4000>=TODAY()-DECISION_RULES!$B$7)*(RAW_DATA!$D$5:$D$4000<=TODAY())*RAW_DATA!$F$5:$F$5000*RAW_DATA!$G$5:$G$5000/100)/SUMIFS(RAW_DATA!$F$5:$F$5000,RAW_DATA!$C$5:$C$5000,A9,RAW_DATA!$D$5:$D$4000,">="&TODAY()-DECISION_RULES!$B$7,RAW_DATA!$D$5:$D$4000,"<="&TODAY())*100,"–") -> 3.4482759 | H9: =IFERROR(VLOOKUP(B9,BENCHMARK!$A:$B,2,FALSE),VLOOKUP("DEFAULT",BENCHMARK!$A:$B,2,FALSE)) -> 180000 | I9: =IF(A9="","-", IF(SUMIFS(RAW_DATA!$J$5:$J$5000,RAW_DATA!$C$5:$C$5000,A9)<DECISION_RULES!$B$5,"CHUA DU DATA", IF(AND(SUMIFS(RAW_DATA!$J$5:$J$5000,RAW_DATA!$C$5:$C$5000,A9)>=DECISION_RULES!$B$5,C9=0,E9=0),"KILL", IF(AND(D9<H9,F9<H9),"SCALE", IF(AND(D9<H9,F9>H9),"WARNING", IF(AND(D9>H9,F9<H9),"TEST","KILL")))))) -> WARNING | J9: =IF(A9="","–",IF(I9="KILL",IF(C9=0,"Da chi tieu nhung 0 conv - tat ngay, kiem tra target va content","Ca 30d va 7d deu kem - nen tat hoac thay content moi"),IF(I9="SCALE","30d va 7d deu tot - co the tang budget 20-30%",IF(I9="WARNING","30d tot nhung 7d dang xau - KHONG scale, theo doi them 3 ngay",IF(I9="TEST","30d chua tot nhung 7d dang cai thien - giu nguyen, cho them 3-5 ngay","Chua du du lieu - can chi tieu "&DECISION_RULES!$B$5&" de danh gia chinh xac"))))) -> 30d tot nhung 7d dang xau - KHONG scale, theo doi them 3 ngay
A10: =IFERROR(__xludf.DUMMYFUNCTION("""COMPUTED_VALUE"""),"DHHQ_Reels_DieuDuongDHKyungin_0925_7878") -> DHHQ_Reels_DieuDuongDHKyungin_0925_7878 | B10: {=IFERROR(INDEX(RAW_DATA!$L$5:$L$4000,MATCH(A10,RAW_DATA!$C$5:$C$4000,0)),"DEFAULT")} -> Du học Hàn Quốc | C10: =IFERROR(SUMPRODUCT((RAW_DATA!C$5:C$2000=A10)*(RAW_DATA!D$5:D$2000>=TODAY()-30)*(RAW_DATA!D$5:D$2000<=TODAY()-1)*RAW_DATA!H$5:H$2000),0) -> 8 | D10: =IF($A10="", "", IFERROR(SUMIFS(RAW_DATA!$J$5:$J$5000, RAW_DATA!$C$5:$C$5000, $A10, RAW_DATA!$D$5:$D$5000, ">="&TODAY()-30, RAW_DATA!$D$5:$D$5000, "<="&TODAY()) / $C10, "–")) -> 93485.75 | E10: =IFERROR(SUMIFS(RAW_DATA!$H$5:$H$4000,RAW_DATA!$C$5:$C$4000,$A10,RAW_DATA!$D$5:$D$4000,">="&TODAY()-7,RAW_DATA!$D$5:$D$4000,"<="&TODAY()),0) -> 4 | F10: =IFERROR(SUMIFS(RAW_DATA!$J$5:$J$4000,RAW_DATA!$C$5:$C$4000,A10,RAW_DATA!$D$5:$D$4000,">="&TODAY()-DECISION_RULES!$B$6,RAW_DATA!$D$5:$D$4000,"<="&TODAY())/E10,"–") -> 123230.5 | G10: =IFERROR(SUMPRODUCT((RAW_DATA!$C$5:$C$5000=A10)*(RAW_DATA!$D$5:$D$4000>=TODAY()-DECISION_RULES!$B$7)*(RAW_DATA!$D$5:$D$4000<=TODAY())*RAW_DATA!$F$5:$F$5000*RAW_DATA!$G$5:$G$5000/100)/SUMIFS(RAW_DATA!$F$5:$F$5000,RAW_DATA!$C$5:$C$5000,A10,RAW_DATA!$D$5:$D$4000,">="&TODAY()-DECISION_RULES!$B$7,RAW_DATA!$D$5:$D$4000,"<="&TODAY())*100,"–") -> 1.8571429 | H10: =IFERROR(VLOOKUP(B10,BENCHMARK!$A:$B,2,FALSE),VLOOKUP("DEFAULT",BENCHMARK!$A:$B,2,FALSE)) -> 180000 | I10: =IF(A10="","-", IF(SUMIFS(RAW_DATA!$J$5:$J$5000,RAW_DATA!$C$5:$C$5000,A10)<DECISION_RULES!$B$5,"CHUA DU DATA", IF(AND(SUMIFS(RAW_DATA!$J$5:$J$5000,RAW_DATA!$C$5:$C$5000,A10)>=DECISION_RULES!$B$5,C10=0,E10=0),"KILL", IF(AND(D10<H10,F10<H10),"SCALE", IF(AND(D10<H10,F10>H10),"WARNING", IF(AND(D10>H10,F10<H10),"TEST","KILL")))))) -> SCALE | J10: =IF(A10="","–",IF(I10="KILL",IF(C10=0,"Da chi tieu nhung 0 conv - tat ngay, kiem tra target va content","Ca 30d va 7d deu kem - nen tat hoac thay content moi"),IF(I10="SCALE","30d va 7d deu tot - co the tang budget 20-30%",IF(I10="WARNING","30d tot nhung 7d dang xau - KHONG scale, theo doi them 3 ngay",IF(I10="TEST","30d chua tot nhung 7d dang cai thien - giu nguyen, cho them 3-5 ngay","Chua du du lieu - can chi tieu "&DECISION_RULES!$B$5&" de danh gia chinh xac"))))) -> 30d va 7d deu tot - co the tang budget 20-30%
A11: =IFERROR(__xludf.DUMMYFUNCTION("""COMPUTED_VALUE"""),"DHND_Album_AnhThatDHS_0424_3960") -> DHND_Album_AnhThatDHS_0424_3960 | B11: {=IFERROR(INDEX(RAW_DATA!$L$5:$L$4000,MATCH(A11,RAW_DATA!$C$5:$C$4000,0)),"DEFAULT")} -> Du học nghề Đức | C11: =IFERROR(SUMPRODUCT((RAW_DATA!C$5:C$2000=A11)*(RAW_DATA!D$5:D$2000>=TODAY()-30)*(RAW_DATA!D$5:D$2000<=TODAY()-1)*RAW_DATA!H$5:H$2000),0) -> 101 | D11: =IF($A11="", "", IFERROR(SUMIFS(RAW_DATA!$J$5:$J$5000, RAW_DATA!$C$5:$C$5000, $A11, RAW_DATA!$D$5:$D$5000, ">="&TODAY()-30, RAW_DATA!$D$5:$D$5000, "<="&TODAY()) / $C11, "–")) -> 117751.19 | E11: =IFERROR(SUMIFS(RAW_DATA!$H$5:$H$4000,RAW_DATA!$C$5:$C$4000,$A11,RAW_DATA!$D$5:$D$4000,">="&TODAY()-7,RAW_DATA!$D$5:$D$4000,"<="&TODAY()),0) -> 18 | F11: =IFERROR(SUMIFS(RAW_DATA!$J$5:$J$4000,RAW_DATA!$C$5:$C$4000,A11,RAW_DATA!$D$5:$D$4000,">="&TODAY()-DECISION_RULES!$B$6,RAW_DATA!$D$5:$D$4000,"<="&TODAY())/E11,"–") -> 138198.67 | G11: =IFERROR(SUMPRODUCT((RAW_DATA!$C$5:$C$5000=A11)*(RAW_DATA!$D$5:$D$4000>=TODAY()-DECISION_RULES!$B$7)*(RAW_DATA!$D$5:$D$4000<=TODAY())*RAW_DATA!$F$5:$F$5000*RAW_DATA!$G$5:$G$5000/100)/SUMIFS(RAW_DATA!$F$5:$F$5000,RAW_DATA!$C$5:$C$5000,A11,RAW_DATA!$D$5:$D$4000,">="&TODAY()-DECISION_RULES!$B$7,RAW_DATA!$D$5:$D$4000,"<="&TODAY())*100,"–") -> 3.2985955 | H11: =IFERROR(VLOOKUP(B11,BENCHMARK!$A:$B,2,FALSE),VLOOKUP("DEFAULT",BENCHMARK!$A:$B,2,FALSE)) -> 150000 | I11: =IF(A11="","-", IF(SUMIFS(RAW_DATA!$J$5:$J$5000,RAW_DATA!$C$5:$C$5000,A11)<DECISION_RULES!$B$5,"CHUA DU DATA", IF(AND(SUMIFS(RAW_DATA!$J$5:$J$5000,RAW_DATA!$C$5:$C$5000,A11)>=DECISION_RULES!$B$5,C11=0,E11=0),"KILL", IF(AND(D11<H11,F11<H11),"SCALE", IF(AND(D11<H11,F11>H11),"WARNING", IF(AND(D11>H11,F11<H11),"TEST","KILL")))))) -> SCALE | J11: =IF(A11="","–",IF(I11="KILL",IF(C11=0,"Da chi tieu nhung 0 conv - tat ngay, kiem tra target va content","Ca 30d va 7d deu kem - nen tat hoac thay content moi"),IF(I11="SCALE","30d va 7d deu tot - co the tang budget 20-30%",IF(I11="WARNING","30d tot nhung 7d dang xau - KHONG scale, theo doi them 3 ngay",IF(I11="TEST","30d chua tot nhung 7d dang cai thien - giu nguyen, cho them 3-5 ngay","Chua du du lieu - can chi tieu "&DECISION_RULES!$B$5&" de danh gia chinh xac"))))) -> 30d va 7d deu tot - co the tang budget 20-30%
A12: =IFERROR(__xludf.DUMMYFUNCTION("""COMPUTED_VALUE"""),"DHND_Photo_ChuyenTiep_1124_9441") -> DHND_Photo_ChuyenTiep_1124_9441 | B12: {=IFERROR(INDEX(RAW_DATA!$L$5:$L$4000,MATCH(A12,RAW_DATA!$C$5:$C$4000,0)),"DEFAULT")} -> Du học nghề Đức | C12: =IFERROR(SUMPRODUCT((RAW_DATA!C$5:C$2000=A12)*(RAW_DATA!D$5:D$2000>=TODAY()-30)*(RAW_DATA!D$5:D$2000<=TODAY()-1)*RAW_DATA!H$5:H$2000),0) -> 1 | D12: =IF($A12="", "", IFERROR(SUMIFS(RAW_DATA!$J$5:$J$5000, RAW_DATA!$C$5:$C$5000, $A12, RAW_DATA!$D$5:$D$5000, ">="&TODAY()-30, RAW_DATA!$D$5:$D$5000, "<="&TODAY()) / $C12, "–")) -> 139744 | E12: =IFERROR(SUMIFS(RAW_DATA!$H$5:$H$4000,RAW_DATA!$C$5:$C$4000,$A12,RAW_DATA!$D$5:$D$4000,">="&TODAY()-7,RAW_DATA!$D$5:$D$4000,"<="&TODAY()),0) -> 1 | F12: =IFERROR(SUMIFS(RAW_DATA!$J$5:$J$4000,RAW_DATA!$C$5:$C$4000,A12,RAW_DATA!$D$5:$D$4000,">="&TODAY()-DECISION_RULES!$B$6,RAW_DATA!$D$5:$D$4000,"<="&TODAY())/E12,"–") -> 128837 | G12: =IFERROR(SUMPRODUCT((RAW_DATA!$C$5:$C$5000=A12)*(RAW_DATA!$D$5:$D$4000>=TODAY()-DECISION_RULES!$B$7)*(RAW_DATA!$D$5:$D$4000<=TODAY())*RAW_DATA!$F$5:$F$5000*RAW_DATA!$G$5:$G$5000/100)/SUMIFS(RAW_DATA!$F$5:$F$5000,RAW_DATA!$C$5:$C$5000,A12,RAW_DATA!$D$5:$D$4000,">="&TODAY()-DECISION_RULES!$B$7,RAW_DATA!$D$5:$D$4000,"<="&TODAY())*100,"–") -> 2.1711367 | H12: =IFERROR(VLOOKUP(B12,BENCHMARK!$A:$B,2,FALSE),VLOOKUP("DEFAULT",BENCHMARK!$A:$B,2,FALSE)) -> 150000 | I12: =IF(A12="","-", IF(SUMIFS(RAW_DATA!$J$5:$J$5000,RAW_DATA!$C$5:$C$5000,A12)<DECISION_RULES!$B$5,"CHUA DU DATA", IF(AND(SUMIFS(RAW_DATA!$J$5:$J$5000,RAW_DATA!$C$5:$C$5000,A12)>=DECISION_RULES!$B$5,C12=0,E12=0),"KILL", IF(AND(D12<H12,F12<H12),"SCALE", IF(AND(D12<H12,F12>H12),"WARNING", IF(AND(D12>H12,F12<H12),"TEST","KILL")))))) -> SCALE | J12: =IF(A12="","–",IF(I12="KILL",IF(C12=0,"Da chi tieu nhung 0 conv - tat ngay, kiem tra target va content","Ca 30d va 7d deu kem - nen tat hoac thay content moi"),IF(I12="SCALE","30d va 7d deu tot - co the tang budget 20-30%",IF(I12="WARNING","30d tot nhung 7d dang xau - KHONG scale, theo doi them 3 ngay",IF(I12="TEST","30d chua tot nhung 7d dang cai thien - giu nguyen, cho them 3-5 ngay","Chua du du lieu - can chi tieu "&DECISION_RULES!$B$5&" de danh gia chinh xac"))))) -> 30d va 7d deu tot - co the tang budget 20-30%
A13: =IFERROR(__xludf.DUMMYFUNCTION("""COMPUTED_VALUE"""),"DHND_Photo_DieuDuong2026_0126_3960") -> DHND_Photo_DieuDuong2026_0126_3960 | B13: {=IFERROR(INDEX(RAW_DATA!$L$5:$L$4000,MATCH(A13,RAW_DATA!$C$5:$C$4000,0)),"DEFAULT")} -> Du học nghề Đức | C13: =IFERROR(SUMPRODUCT((RAW_DATA!C$5:C$2000=A13)*(RAW_DATA!D$5:D$2000>=TODAY()-30)*(RAW_DATA!D$5:D$2000<=TODAY()-1)*RAW_DATA!H$5:H$2000),0) -> 18 | D13: =IF($A13="", "", IFERROR(SUMIFS(RAW_DATA!$J$5:$J$5000, RAW_DATA!$C$5:$C$5000, $A13, RAW_DATA!$D$5:$D$5000, ">="&TODAY()-30, RAW_DATA!$D$5:$D$5000, "<="&TODAY()) / $C13, "–")) -> 101974.44 | E13: =IFERROR(SUMIFS(RAW_DATA!$H$5:$H$4000,RAW_DATA!$C$5:$C$4000,$A13,RAW_DATA!$D$5:$D$4000,">="&TODAY()-7,RAW_DATA!$D$5:$D$4000,"<="&TODAY()),0) -> 7 | F13: =IFERROR(SUMIFS(RAW_DATA!$J$5:$J$4000,RAW_DATA!$C$5:$C$4000,A13,RAW_DATA!$D$5:$D$4000,">="&TODAY()-DECISION_RULES!$B$6,RAW_DATA!$D$5:$D$4000,"<="&TODAY())/E13,"–") -> 62974.143 | G13: =IFERROR(SUMPRODUCT((RAW_DATA!$C$5:$C$5000=A13)*(RAW_DATA!$D$5:$D$4000>=TODAY()-DECISION_RULES!$B$7)*(RAW_DATA!$D$5:$D$4000<=TODAY())*RAW_DATA!$F$5:$F$5000*RAW_DATA!$G$5:$G$5000/100)/SUMIFS(RAW_DATA!$F$5:$F$5000,RAW_DATA!$C$5:$C$5000,A13,RAW_DATA!$D$5:$D$4000,">="&TODAY()-DECISION_RULES!$B$7,RAW_DATA!$D$5:$D$4000,"<="&TODAY())*100,"–") -> 2.8258888 | H13: =IFERROR(VLOOKUP(B13,BENCHMARK!$A:$B,2,FALSE),VLOOKUP("DEFAULT",BENCHMARK!$A:$B,2,FALSE)) -> 150000 | I13: =IF(A13="","-", IF(SUMIFS(RAW_DATA!$J$5:$J$5000,RAW_DATA!$C$5:$C$5000,A13)<DECISION_RULES!$B$5,"CHUA DU DATA", IF(AND(SUMIFS(RAW_DATA!$J$5:$J$5000,RAW_DATA!$C$5:$C$5000,A13)>=DECISION_RULES!$B$5,C13=0,E13=0),"KILL", IF(AND(D13<H13,F13<H13),"SCALE", IF(AND(D13<H13,F13>H13),"WARNING", IF(AND(D13>H13,F13<H13),"TEST","KILL")))))) -> SCALE | J13: =IF(A13="","–",IF(I13="KILL",IF(C13=0,"Da chi tieu nhung 0 conv - tat ngay, kiem tra target va content","Ca 30d va 7d deu kem - nen tat hoac thay content moi"),IF(I13="SCALE","30d va 7d deu tot - co the tang budget 20-30%",IF(I13="WARNING","30d tot nhung 7d dang xau - KHONG scale, theo doi them 3 ngay",IF(I13="TEST","30d chua tot nhung 7d dang cai thien - giu nguyen, cho them 3-5 ngay","Chua du du lieu - can chi tieu "&DECISION_RULES!$B$5&" de danh gia chinh xac"))))) -> 30d va 7d deu tot - co the tang budget 20-30%
A14: =IFERROR(__xludf.DUMMYFUNCTION("""COMPUTED_VALUE"""),"DHND_Reels_DaiHoc2005_0124_0622") -> DHND_Reels_DaiHoc2005_0124_0622 | B14: {=IFERROR(INDEX(RAW_DATA!$L$5:$L$4000,MATCH(A14,RAW_DATA!$C$5:$C$4000,0)),"DEFAULT")} -> Du học nghề Đức | C14: =IFERROR(SUMPRODUCT((RAW_DATA!C$5:C$2000=A14)*(RAW_DATA!D$5:D$2000>=TODAY()-30)*(RAW_DATA!D$5:D$2000<=TODAY()-1)*RAW_DATA!H$5:H$2000),0) -> 167 | D14: =IF($A14="", "", IFERROR(SUMIFS(RAW_DATA!$J$5:$J$5000, RAW_DATA!$C$5:$C$5000, $A14, RAW_DATA!$D$5:$D$5000, ">="&TODAY()-30, RAW_DATA!$D$5:$D$5000, "<="&TODAY()) / $C14, "–")) -> 78877.395 | E14: =IFERROR(SUMIFS(RAW_DATA!$H$5:$H$4000,RAW_DATA!$C$5:$C$4000,$A14,RAW_DATA!$D$5:$D$4000,">="&TODAY()-7,RAW_DATA!$D$5:$D$4000,"<="&TODAY()),0) -> 33 | F14: =IFERROR(SUMIFS(RAW_DATA!$J$5:$J$4000,RAW_DATA!$C$5:$C$4000,A14,RAW_DATA!$D$5:$D$4000,">="&TODAY()-DECISION_RULES!$B$6,RAW_DATA!$D$5:$D$4000,"<="&TODAY())/E14,"–") -> 94463.848 | G14: =IFERROR(SUMPRODUCT((RAW_DATA!$C$5:$C$5000=A14)*(RAW_DATA!$D$5:$D$4000>=TODAY()-DECISION_RULES!$B$7)*(RAW_DATA!$D$5:$D$4000<=TODAY())*RAW_DATA!$F$5:$F$5000*RAW_DATA!$G$5:$G$5000/100)/SUMIFS(RAW_DATA!$F$5:$F$5000,RAW_DATA!$C$5:$C$5000,A14,RAW_DATA!$D$5:$D$4000,">="&TODAY()-DECISION_RULES!$B$7,RAW_DATA!$D$5:$D$4000,"<="&TODAY())*100,"–") -> 2.7442028 | H14: =IFERROR(VLOOKUP(B14,BENCHMARK!$A:$B,2,FALSE),VLOOKUP("DEFAULT",BENCHMARK!$A:$B,2,FALSE)) -> 150000 | I14: =IF(A14="","-", IF(SUMIFS(RAW_DATA!$J$5:$J$5000,RAW_DATA!$C$5:$C$5000,A14)<DECISION_RULES!$B$5,"CHUA DU DATA", IF(AND(SUMIFS(RAW_DATA!$J$5:$J$5000,RAW_DATA!$C$5:$C$5000,A14)>=DECISION_RULES!$B$5,C14=0,E14=0),"KILL", IF(AND(D14<H14,F14<H14),"SCALE", IF(AND(D14<H14,F14>H14),"WARNING", IF(AND(D14>H14,F14<H14),"TEST","KILL")))))) -> SCALE | J14: =IF(A14="","–",IF(I14="KILL",IF(C14=0,"Da chi tieu nhung 0 conv - tat ngay, kiem tra target va content","Ca 30d va 7d deu kem - nen tat hoac thay content moi"),IF(I14="SCALE","30d va 7d deu tot - co the tang budget 20-30%",IF(I14="WARNING","30d tot nhung 7d dang xau - KHONG scale, theo doi them 3 ngay",IF(I14="TEST","30d chua tot nhung 7d dang cai thien - giu nguyen, cho them 3-5 ngay","Chua du du lieu - can chi tieu "&DECISION_RULES!$B$5&" de danh gia chinh xac"))))) -> 30d va 7d deu tot - co the tang budget 20-30%
A15: =IFERROR(__xludf.DUMMYFUNCTION("""COMPUTED_VALUE"""),"DHND_Reels_DieuDuong2026_0126_3960") -> DHND_Reels_DieuDuong2026_0126_3960 | B15: {=IFERROR(INDEX(RAW_DATA!$L$5:$L$4000,MATCH(A15,RAW_DATA!$C$5:$C$4000,0)),"DEFAULT")} -> Du học nghề Đức | C15: =IFERROR(SUMPRODUCT((RAW_DATA!C$5:C$2000=A15)*(RAW_DATA!D$5:D$2000>=TODAY()-30)*(RAW_DATA!D$5:D$2000<=TODAY()-1)*RAW_DATA!H$5:H$2000),0) -> 41 | D15: =IF($A15="", "", IFERROR(SUMIFS(RAW_DATA!$J$5:$J$5000, RAW_DATA!$C$5:$C$5000, $A15, RAW_DATA!$D$5:$D$5000, ">="&TODAY()-30, RAW_DATA!$D$5:$D$5000, "<="&TODAY()) / $C15, "–")) -> 137164.51 | E15: =IFERROR(SUMIFS(RAW_DATA!$H$5:$H$4000,RAW_DATA!$C$5:$C$4000,$A15,RAW_DATA!$D$5:$D$4000,">="&TODAY()-7,RAW_DATA!$D$5:$D$4000,"<="&TODAY()),0) -> 8 | F15: =IFERROR(SUMIFS(RAW_DATA!$J$5:$J$4000,RAW_DATA!$C$5:$C$4000,A15,RAW_DATA!$D$5:$D$4000,">="&TODAY()-DECISION_RULES!$B$6,RAW_DATA!$D$5:$D$4000,"<="&TODAY())/E15,"–") -> 152227.5 | G15: =IFERROR(SUMPRODUCT((RAW_DATA!$C$5:$C$5000=A15)*(RAW_DATA!$D$5:$D$4000>=TODAY()-DECISION_RULES!$B$7)*(RAW_DATA!$D$5:$D$4000<=TODAY())*RAW_DATA!$F$5:$F$5000*RAW_DATA!$G$5:$G$5000/100)/SUMIFS(RAW_DATA!$F$5:$F$5000,RAW_DATA!$C$5:$C$5000,A15,RAW_DATA!$D$5:$D$4000,">="&TODAY()-DECISION_RULES!$B$7,RAW_DATA!$D$5:$D$4000,"<="&TODAY())*100,"–") -> 2.9810684 | H15: =IFERROR(VLOOKUP(B15,BENCHMARK!$A:$B,2,FALSE),VLOOKUP("DEFAULT",BENCHMARK!$A:$B,2,FALSE)) -> 150000 | I15: =IF(A15="","-", IF(SUMIFS(RAW_DATA!$J$5:$J$5000,RAW_DATA!$C$5:$C$5000,A15)<DECISION_RULES!$B$5,"CHUA DU DATA", IF(AND(SUMIFS(RAW_DATA!$J$5:$J$5000,RAW_DATA!$C$5:$C$5000,A15)>=DECISION_RULES!$B$5,C15=0,E15=0),"KILL", IF(AND(D15<H15,F15<H15),"SCALE", IF(AND(D15<H15,F15>H15),"WARNING", IF(AND(D15>H15,F15<H15),"TEST","KILL")))))) -> WARNING | J15: =IF(A15="","–",IF(I15="KILL",IF(C15=0,"Da chi tieu nhung 0 conv - tat ngay, kiem tra target va content","Ca 30d va 7d deu kem - nen tat hoac thay content moi"),IF(I15="SCALE","30d va 7d deu tot - co the tang budget 20-30%",IF(I15="WARNING","30d tot nhung 7d dang xau - KHONG scale, theo doi them 3 ngay",IF(I15="TEST","30d chua tot nhung 7d dang cai thien - giu nguyen, cho them 3-5 ngay","Chua du du lieu - can chi tieu "&DECISION_RULES!$B$5&" de danh gia chinh xac"))))) -> 30d tot nhung 7d dang xau - KHONG scale, theo doi them 3 ngay
A16: =IFERROR(__xludf.DUMMYFUNCTION("""COMPUTED_VALUE"""),"DHND_Reels_HuongDiTrienVong_0226_3960") -> DHND_Reels_HuongDiTrienVong_0226_3960 | B16: {=IFERROR(INDEX(RAW_DATA!$L$5:$L$4000,MATCH(A16,RAW_DATA!$C$5:$C$4000,0)),"DEFAULT")} -> Du học nghề Đức | C16: =IFERROR(SUMPRODUCT((RAW_DATA!C$5:C$2000=A16)*(RAW_DATA!D$5:D$2000>=TODAY()-30)*(RAW_DATA!D$5:D$2000<=TODAY()-1)*RAW_DATA!H$5:H$2000),0) -> 30 | D16: =IF($A16="", "", IFERROR(SUMIFS(RAW_DATA!$J$5:$J$5000, RAW_DATA!$C$5:$C$5000, $A16, RAW_DATA!$D$5:$D$5000, ">="&TODAY()-30, RAW_DATA!$D$5:$D$5000, "<="&TODAY()) / $C16, "–")) -> 126224.1 | E16: =IFERROR(SUMIFS(RAW_DATA!$H$5:$H$4000,RAW_DATA!$C$5:$C$4000,$A16,RAW_DATA!$D$5:$D$4000,">="&TODAY()-7,RAW_DATA!$D$5:$D$4000,"<="&TODAY()),0) -> 6 | F16: =IFERROR(SUMIFS(RAW_DATA!$J$5:$J$4000,RAW_DATA!$C$5:$C$4000,A16,RAW_DATA!$D$5:$D$4000,">="&TODAY()-DECISION_RULES!$B$6,RAW_DATA!$D$5:$D$4000,"<="&TODAY())/E16,"–") -> 189918.33 | G16: =IFERROR(SUMPRODUCT((RAW_DATA!$C$5:$C$5000=A16)*(RAW_DATA!$D$5:$D$4000>=TODAY()-DECISION_RULES!$B$7)*(RAW_DATA!$D$5:$D$4000<=TODAY())*RAW_DATA!$F$5:$F$5000*RAW_DATA!$G$5:$G$5000/100)/SUMIFS(RAW_DATA!$F$5:$F$5000,RAW_DATA!$C$5:$C$5000,A16,RAW_DATA!$D$5:$D$4000,">="&TODAY()-DECISION_RULES!$B$7,RAW_DATA!$D$5:$D$4000,"<="&TODAY())*100,"–") -> 2.041704 | H16: =IFERROR(VLOOKUP(B16,BENCHMARK!$A:$B,2,FALSE),VLOOKUP("DEFAULT",BENCHMARK!$A:$B,2,FALSE)) -> 150000 | I16: =IF(A16="","-", IF(SUMIFS(RAW_DATA!$J$5:$J$5000,RAW_DATA!$C$5:$C$5000,A16)<DECISION_RULES!$B$5,"CHUA DU DATA", IF(AND(SUMIFS(RAW_DATA!$J$5:$J$5000,RAW_DATA!$C$5:$C$5000,A16)>=DECISION_RULES!$B$5,C16=0,E16=0),"KILL", IF(AND(D16<H16,F16<H16),"SCALE", IF(AND(D16<H16,F16>H16),"WARNING", IF(AND(D16>H16,F16<H16),"TEST","KILL")))))) -> WARNING | J16: =IF(A16="","–",IF(I16="KILL",IF(C16=0,"Da chi tieu nhung 0 conv - tat ngay, kiem tra target va content","Ca 30d va 7d deu kem - nen tat hoac thay content moi"),IF(I16="SCALE","30d va 7d deu tot - co the tang budget 20-30%",IF(I16="WARNING","30d tot nhung 7d dang xau - KHONG scale, theo doi them 3 ngay",IF(I16="TEST","30d chua tot nhung 7d dang cai thien - giu nguyen, cho them 3-5 ngay","Chua du du lieu - can chi tieu "&DECISION_RULES!$B$5&" de danh gia chinh xac"))))) -> 30d tot nhung 7d dang xau - KHONG scale, theo doi them 3 ngay
A17: =IFERROR(__xludf.DUMMYFUNCTION("""COMPUTED_VALUE"""),"DHND_Reels_HuongDiTrienVong_0924_2253") -> DHND_Reels_HuongDiTrienVong_0924_2253 | B17: {=IFERROR(INDEX(RAW_DATA!$L$5:$L$4000,MATCH(A17,RAW_DATA!$C$5:$C$4000,0)),"DEFAULT")} -> Du học nghề Đức | C17: =IFERROR(SUMPRODUCT((RAW_DATA!C$5:C$2000=A17)*(RAW_DATA!D$5:D$2000>=TODAY()-30)*(RAW_DATA!D$5:D$2000<=TODAY()-1)*RAW_DATA!H$5:H$2000),0) -> 82 | D17: =IF($A17="", "", IFERROR(SUMIFS(RAW_DATA!$J$5:$J$5000, RAW_DATA!$C$5:$C$5000, $A17, RAW_DATA!$D$5:$D$5000, ">="&TODAY()-30, RAW_DATA!$D$5:$D$5000, "<="&TODAY()) / $C17, "–")) -> 105501.02 | E17: =IFERROR(SUMIFS(RAW_DATA!$H$5:$H$4000,RAW_DATA!$C$5:$C$4000,$A17,RAW_DATA!$D$5:$D$4000,">="&TODAY()-7,RAW_DATA!$D$5:$D$4000,"<="&TODAY()),0) -> 16 | F17: =IFERROR(SUMIFS(RAW_DATA!$J$5:$J$4000,RAW_DATA!$C$5:$C$4000,A17,RAW_DATA!$D$5:$D$4000,">="&TODAY()-DECISION_RULES!$B$6,RAW_DATA!$D$5:$D$4000,"<="&TODAY())/E17,"–") -> 119731.25 | G17: =IFERROR(SUMPRODUCT((RAW_DATA!$C$5:$C$5000=A17)*(RAW_DATA!$D$5:$D$4000>=TODAY()-DECISION_RULES!$B$7)*(RAW_DATA!$D$5:$D$4000<=TODAY())*RAW_DATA!$F$5:$F$5000*RAW_DATA!$G$5:$G$5000/100)/SUMIFS(RAW_DATA!$F$5:$F$5000,RAW_DATA!$C$5:$C$5000,A17,RAW_DATA!$D$5:$D$4000,">="&TODAY()-DECISION_RULES!$B$7,RAW_DATA!$D$5:$D$4000,"<="&TODAY())*100,"–") -> 2.1197055 | H17: =IFERROR(VLOOKUP(B17,BENCHMARK!$A:$B,2,FALSE),VLOOKUP("DEFAULT",BENCHMARK!$A:$B,2,FALSE)) -> 150000 | I17: =IF(A17="","-", IF(SUMIFS(RAW_DATA!$J$5:$J$5000,RAW_DATA!$C$5:$C$5000,A17)<DECISION_RULES!$B$5,"CHUA DU DATA", IF(AND(SUMIFS(RAW_DATA!$J$5:$J$5000,RAW_DATA!$C$5:$C$5000,A17)>=DECISION_RULES!$B$5,C17=0,E17=0),"KILL", IF(AND(D17<H17,F17<H17),"SCALE", IF(AND(D17<H17,F17>H17),"WARNING", IF(AND(D17>H17,F17<H17),"TEST","KILL")))))) -> SCALE | J17: =IF(A17="","–",IF(I17="KILL",IF(C17=0,"Da chi tieu nhung 0 conv - tat ngay, kiem tra target va content","Ca 30d va 7d deu kem - nen tat hoac thay content moi"),IF(I17="SCALE","30d va 7d deu tot - co the tang budget 20-30%",IF(I17="WARNING","30d tot nhung 7d dang xau - KHONG scale, theo doi them 3 ngay",IF(I17="TEST","30d chua tot nhung 7d dang cai thien - giu nguyen, cho them 3-5 ngay","Chua du du lieu - can chi tieu "&DECISION_RULES!$B$5&" de danh gia chinh xac"))))) -> 30d va 7d deu tot - co the tang budget 20-30%
A18: =IFERROR(__xludf.DUMMYFUNCTION("""COMPUTED_VALUE"""),"Duc_Album_Chung_NangTrinhCapToc_0925_5171") -> Duc_Album_Chung_NangTrinhCapToc_0925_5171 | B18: {=IFERROR(INDEX(RAW_DATA!$L$5:$L$4000,MATCH(A18,RAW_DATA!$C$5:$C$4000,0)),"DEFAULT")} -> Tiếng Đức | C18: =IFERROR(SUMPRODUCT((RAW_DATA!C$5:C$2000=A18)*(RAW_DATA!D$5:D$2000>=TODAY()-30)*(RAW_DATA!D$5:D$2000<=TODAY()-1)*RAW_DATA!H$5:H$2000),0) -> 56 | D18: =IF($A18="", "", IFERROR(SUMIFS(RAW_DATA!$J$5:$J$5000, RAW_DATA!$C$5:$C$5000, $A18, RAW_DATA!$D$5:$D$5000, ">="&TODAY()-30, RAW_DATA!$D$5:$D$5000, "<="&TODAY()) / $C18, "–")) -> 116264.43 | E18: =IFERROR(SUMIFS(RAW_DATA!$H$5:$H$4000,RAW_DATA!$C$5:$C$4000,$A18,RAW_DATA!$D$5:$D$4000,">="&TODAY()-7,RAW_DATA!$D$5:$D$4000,"<="&TODAY()),0) -> 14 | F18: =IFERROR(SUMIFS(RAW_DATA!$J$5:$J$4000,RAW_DATA!$C$5:$C$4000,A18,RAW_DATA!$D$5:$D$4000,">="&TODAY()-DECISION_RULES!$B$6,RAW_DATA!$D$5:$D$4000,"<="&TODAY())/E18,"–") -> 122518.93 | G18: =IFERROR(SUMPRODUCT((RAW_DATA!$C$5:$C$5000=A18)*(RAW_DATA!$D$5:$D$4000>=TODAY()-DECISION_RULES!$B$7)*(RAW_DATA!$D$5:$D$4000<=TODAY())*RAW_DATA!$F$5:$F$5000*RAW_DATA!$G$5:$G$5000/100)/SUMIFS(RAW_DATA!$F$5:$F$5000,RAW_DATA!$C$5:$C$5000,A18,RAW_DATA!$D$5:$D$4000,">="&TODAY()-DECISION_RULES!$B$7,RAW_DATA!$D$5:$D$4000,"<="&TODAY())*100,"–") -> 1.1352962 | H18: =IFERROR(VLOOKUP(B18,BENCHMARK!$A:$B,2,FALSE),VLOOKUP("DEFAULT",BENCHMARK!$A:$B,2,FALSE)) -> 150000 | I18: =IF(A18="","-", IF(SUMIFS(RAW_DATA!$J$5:$J$5000,RAW_DATA!$C$5:$C$5000,A18)<DECISION_RULES!$B$5,"CHUA DU DATA", IF(AND(SUMIFS(RAW_DATA!$J$5:$J$5000,RAW_DATA!$C$5:$C$5000,A18)>=DECISION_RULES!$B$5,C18=0,E18=0),"KILL", IF(AND(D18<H18,F18<H18),"SCALE", IF(AND(D18<H18,F18>H18),"WARNING", IF(AND(D18>H18,F18<H18),"TEST","KILL")))))) -> SCALE | J18: =IF(A18="","–",IF(I18="KILL",IF(C18=0,"Da chi tieu nhung 0 conv - tat ngay, kiem tra target va content","Ca 30d va 7d deu kem - nen tat hoac thay content moi"),IF(I18="SCALE","30d va 7d deu tot - co the tang budget 20-30%",IF(I18="WARNING","30d tot nhung 7d dang xau - KHONG scale, theo doi them 3 ngay",IF(I18="TEST","30d chua tot nhung 7d dang cai thien - giu nguyen, cho them 3-5 ngay","Chua du du lieu - can chi tieu "&DECISION_RULES!$B$5&" de danh gia chinh xac"))))) -> 30d va 7d deu tot - co the tang budget 20-30%
